Exception in thread Thread-1 (create_graph):
                                            Traceback (most recent call last):
                                                                                File "/usr/lib/python3.11/threading.py", line 1038, in _bootstrap_inner
         self.run()
                     File "/usr/lib/python3.11/threading.py", line 975, in run
                                                                                  self._target(*self._args, **self._kwargs)
                                                                                                                             File "/home/htc/jschlieffen/flesnet_flesctl/flesnet/contrib/flesctl/zib_flesctl/monitoring.py", line 81, in create_graph
                                                                                                       for key,val in data_dict.items():
                                                                                                                                                           ^^^^^^^^^^^^^^^
                        AttributeError: '_curses.window' object has no attribute 'items'







Exception in thread Thread-1 (create_graph):
                                            Traceback (most recent call last):
                                                                                File "/usr/lib/python3.11/threading.py", line 1038, in _bootstrap_inner
         self.run()
                     File "/usr/lib/python3.11/threading.py", line 975, in run
                                                                                  self._target(*self._args, **self._kwargs)
                                                                                                                             File "/home/htc/jschlieffen/flesnet_flesctl/flesnet/contrib/flesctl/zib_flesctl/monitoring.py", line 83, in create_graph
                                                                                                       data[key]['data'].append(val['current_data'])
      ~~~~^^^^^
               KeyError: 'logs/entry_node_htc-cmp011.log'

xception in thread Thread-1 (create_graph):
                                           Traceback (most recent call last):
                                                                               File "/usr/lib/python3.11/threading.py", line 1038, in _bootstrap_inner
        self.run()
                    File "/usr/lib/python3.11/threading.py", line 975, in run
                                                                                 self._target(*self._args, **self._kwargs)
                                                                                                                            File "/home/htc/jschlieffen/flesnet_flesctl/flesnet/contrib/flesctl/zib_flesctl/monitoring.py", line 87, in create_graph
                                                                                                      data[key]['data'].append(val['current_data'])
     ~~~~^^^^^
              KeyError: 'logs/entry_node_htc-cmp011.log'
